Workbook

Sheet 입력1(학교시설명 등 기본사항 입력) 보고서1,2
A1: 1. 개요
B2: 학교명 (시설명) | C2: 평촌경영고등학교 | F2: 교장 | H2: 손옥기 | O2: 시료번호
B3: 소재지 | C3: 경기도 안양시 동안구 학의로 186
B4: 설립구분 | C4: 공립 | F4: 교실수 | H4: 일반 | I4: 33 | J4: 특별 | K4: 31
B5: 전화번호 | C5: 031-387-0274 | F5: FAX번호 | H5: 031-387-0275
B6: 설비현항 | C6: 냉방 | D6: 중앙 | E6: - | F6: 개별 | H6: 125 | I6: 먹는물 | J6: 상수도
C7: 난방 | D7: 중앙 | E7: - | F7: 개별 | H7: 125 | I7: 저수조 | J7: 3
C8: 환기 | D8: 중앙 | E8: - | F8: 개별 | H8: - | I8: 정수기 | J8: 38
B9: 급식시설 | C9: 조리실 | D9: ○ | E9: 식당 | F9: ○ | H9: 체육장 | I9: 마사토
B10: 체육관 및 강당 | C10: 체육관 | D10: 1 | E10: 강당 | F10: - | H10: 기숙사 | I10: × | J10: 신축년도 | K10: -
A12: 2. 학교시설 환경 측정 개요
B13: 측정일자 | C13: 2026.06.10 | F13: 측정시간 | I13: 13:00 ~ 15:10
B14: 측정장소 | C14: 2-11, 2-4, (도제)회계실무실습실, 1-9, 1-7, (도제)세무실습실, 급식실, 체육관, 보건실, 교무실, 1-12, 2-12, 스포티존
B15: 측정장소 | C15: 소속 | D15: 한국환경보건연구소(주) | F15: 성명 | I15: 박정식
B16: 측정조건 | C16: 온도 | D16: 습도 | E16: 기압 | F16: 소음 | G16: CO2 | H16: PM10 | I16: PM2.5 | J16: 오존 | K16: 환기장치
C17: 27.2 | D17: 40.6 | E17: 1005.2 | F17: 51.2 | G17: 429 | H17: 26 | I17: 24 | J17: 0.053 | K17: 자연

Sheet 입력2(측정)
A1: 분석자 | B1: 유재혁
A2: 검사항목 | B2: 검사조건 | D2: 검사 | E2: 검사결과 | O2: 측정장비 | R2: 최소 | S2: 최대 | T2: 평균
B3: 검사장소 | C3: 검사시간 | E3: 측정값 | M3: 기압
A5: 온도 | B5: 5층 2-11반 | C5: 14:02 ~ 14:12 | D5: 3 | E5: 25.8 | G5: 25.2 | J5: 25.5 | M5: 1004 | O5: KEH-KW-01 | Q5: 0 | R5: =MIN(E5:L5) -> 25.2 | S5: =MAX(E5:L5) -> 25.8 | T5: =AVERAGE(E5:L5) -> 25.5
B6: 4층 2-4반 | C6: 14:13 ~ 14:23 | D6: 3 | E6: 24.9 | G6: 25.1 | J6: 25.3 | M6: 1004.3 | Q6: 0 | R6: =MIN(E6:L6) -> 24.9 | S6: =MAX(E6:L6) -> 25.3 | T6: =AVERAGE(E6:L6) -> 25.1
B7: 1층 (도제)회계실무실습실 | C7: 15:00 ~ 15:10 | D7: 3 | E7: 26.2 | G7: 25.7 | J7: 25.3 | M7: 1005.3 | Q7: - | R7: =MIN(E7:L7) -> 25.3 | S7: =MAX(E7:L7) -> 26.2 | T7: =AVERAGE(E7:L7) -> 25.733333
D8: 3 | Q8: - | R8: =MIN(E8:L8) -> 0 | S8: =MAX(E8:L8) -> 0 | T8: =AVERAGE(E8:L8) -> #DIV/0! | U8: 유치원 수업중
B9: 1층 1-12반 | C9: 13:12 ~ 14:12 | D9: 1 | E9: 26.6 | M9: 1005.5 | Q9: 0 | R9: =MIN(E9:L9) -> 26.6 | S9: =MAX(E9:L9) -> 26.6 | T9: =AVERAGE(E9:L9) -> 26.6 | U9: 틀별점검항목
B10: 2층 2-12반 | C10: 14:05 ~ 15:05 | D10: 1 | E10: 25.4 | M10: 1005.4 | Q10: 0 | R10: =MIN(E10:L10) -> 25.4 | S10: =MAX(E10:L10) -> 25.4 | T10: =AVERAGE(E10:L10) -> 25.4
B11: 1층 스포티존 | C11: 13:00 ~ 14:00 | D11: 1 | E11: 24.3 | M11: 1005.7 | Q11: - | R11: =MIN(E11:L11) -> 24.3 | S11: =MAX(E11:L11) -> 24.3 | T11: =AVERAGE(E11:L11) -> 24.3
A12: 습도 | B12: =B5 -> 5층 2-11반 | C12: =C5 -> 14:02 ~ 14:12 | D12: 3 | E12: 40.47 | G12: 41.1 | J12: 42.6 | M12: - | O12: =O5 -> KEH-KW-01 | R12: =MIN(E12:L12) -> 40.47 | S12: =MAX(E12:L12) -> 42.6 | T12: =AVERAGE(E12:L12) -> 41.39
B13: =B6 -> 4층 2-4반 | C13: =C6 -> 14:13 ~ 14:23 | D13: 3 | E13: 46.9 | G13: 44.8 | J13: 45.3 | M13: - | R13: =MIN(E13:L13) -> 44.8 | S13: =MAX(E13:L13) -> 46.9 | T13: =AVERAGE(E13:L13) -> 45.666667
B14: =B7 -> 1층 (도제)회계실무실습실 | C14: =C7 -> 15:00 ~ 15:10 | D14: 3 | E14: 50.6 | G14: 52.8 | J14: 51.7 | M14: - | R14: =MIN(E14:L14) -> 50.6 | S14: =MAX(E14:L14) -> 52.8 | T14: =AVERAGE(E14:L14) -> 51.7
B15: =B8 -> 0 | C15: =C8 -> 0 | D15: 3 | M15: - | R15: =MIN(E15:L15) -> 0 | S15: =MAX(E15:L15) -> 0 | T15: =AVERAGE(E15:L15) -> #DIV/0! | U15: 유치원 수업중
B16: =B9 -> 1층 1-12반 | C16: =C9 -> 13:12 ~ 14:12 | D16: 1 | E16: 45.2 | M16: - | R16: =MIN(E16:L16) -> 45.2 | S16: =MAX(E16:L16) -> 45.2 | T16: =AVERAGE(E16:L16) -> 45.2 | U16: 틀별점검항목
B17: =B10 -> 2층 2-12반 | C17: =C10 -> 14:05 ~ 15:05 | D17: 1 | E17: 48.2 | M17: - | R17: =MIN(E17:L17) -> 48.2 | S17: =MAX(E17:L17) -> 48.2 | T17: =AVERAGE(E17:L17) -> 48.2
B18: =B11 -> 1층 스포티존 | C18: =C11 -> 13:00 ~ 14:00 | D18: 1 | E18: 40 | M18: - | R18: =MIN(E18:L18) -> 40 | S18: =MAX(E18:L18) -> 40 | T18: =AVERAGE(E18:L18) -> 40
A19: 미세먼지 | B19: =B5 -> 5층 2-11반 | C19: =C5 -> 14:02 ~ 14:12 | D19: 5 | E19: 11 | G19: 13 | I19: 12 | K19: 11 | M19: 12 | O19: =O12 -> KEH-KW-01 | Q19: 0 | R19: =MIN(E19:N19) -> 11 | S19: =MAX(E19:N19) -> 13 | T19: =AVERAGE(E19:N19) -> 11.8
B20: =B6 -> 4층 2-4반 | C20: =C6 -> 14:13 ~ 14:23 | D20: 5 | E20: 18 | G20: 17 | I20: 16 | K20: 16 | M20: 17 | Q20: 0 | R20: =MIN(E20:N20) -> 16 | S20: =MAX(E20:N20) -> 18 | T20: =AVERAGE(E20:N20) -> 16.8
B21: =B7 -> 1층 (도제)회계실무실습실 | C21: =C7 -> 15:00 ~ 15:10 | D21: 5 | E21: 15 | G21: 14 | I21: 13 | K21: 14 | M21: 15 | R21: =MIN(E21:N21) -> 13 | S21: =MAX(E21:N21) -> 15 | T21: =AVERAGE(E21:N21) -> 14.2
B22: =B8 -> 0 | C22: =C8 -> 0 | D22: 5 | R22: =MIN(E22:N22) -> 0 | S22: =MAX(E22:N22) -> 0 | T22: =AVERAGE(E22:N22) -> #DIV/0! | U22: 유치원 수업중
B23: 급식시설 | C23: 14:46 ~ 14:56 | D23: 5 | E23: 18 | G23: 17 | I23: 15 | K23: 14 | M23: 15 | R23: =MIN(E23:N23) -> 14 | S23: =MAX(E23:N23) -> 18 | T23: =AVERAGE(E23:N23) -> 15.8 | U23: 급식시설
B24: 체육관 | C24: 13:38 ~ 13:48 | D24: 10 | E24: 26 | G24: 24 | I24: 25 | K24: 24 | M24: 23 | R24: =MIN(E24:N25) -> 23 | S24: =MAX(E24:N25) -> 27 | T24: =AVERAGE(E24:N25) -> 24.9
E25: 25 | G25: 26 | I25: 24 | K25: 25 | M25: 27
D26: 10 | Q26: 0 | R26: =MIN(E26:N27) -> 0 | S26: =MAX(E26:N27) -> 0 | T26: =AVERAGE(E26:N27) -> #DIV/0!
A28: 초미세먼지 | B28: =B5 -> 5층 2-11반 | C28: =C5 -> 14:02 ~ 14:12 | D28: 5 | E28: 10 | G28: 12 | I28: 11 | K28: 10 | M28: 11 | O28: =O19 -> KEH-KW-01 | Q28: 0 | R28: =MIN(E28:N28) -> 10 | S28: =MAX(E28:N28) -> 12 | T28: =AVERAGE(E28:N28) -> 10.8
B29: =B6 -> 4층 2-4반 | C29: =C6 -> 14:13 ~ 14:23 | D29: 5 | E29: 17 | G29: 16 | I29: 15 | K29: 15 | M29: 16 | Q29: 0 | R29: =MIN(E29:N29) -> 15 | S29: =MAX(E29:N29) -> 17 | T29: =AVERAGE(E29:N29) -> 15.8
B30: =B7 -> 1층 (도제)회계실무실습실 | C30: =C7 -> 15:00 ~ 15:10 | D30: =D21 -> 5 | E30: 14 | G30: 13 | I30: 12 | K30: 13 | M30: 14 | R30: =MIN(E30:N30) -> 12 | S30: =MAX(E30:N30) -> 14 | T30: =AVERAGE(E30:N30) -> 13.2
B31: =B8 -> 0 | C31: =C8 -> 0 | D31: 5 | Q31: 0 | R31: =MIN(E31:N31) -> 0 | S31: =MAX(E31:N31) -> 0 | T31: =AVERAGE(E31:N31) -> #DIV/0! | U31: 유치원 수업중
B32: =B23 -> 급식시설 | C32: =C23 -> 14:46 ~ 14:56 | D32: 5 | E32: 17 | G32: 16 | I32: 14 | K32: 13 | M32: 14 | R32: =MIN(E32:N32) -> 13 | S32: =MAX(E32:N32) -> 17 | T32: =AVERAGE(E32:N32) -> 14.8 | U32: 급식시설
A33: 이산화탄소 | B33: =B5 -> 5층 2-11반 | C33: =C5 -> 14:02 ~ 14:12 | D33: 3 | E33: 816 | G33: 842 | J33: 786 | O33: =O28 -> KEH-KW-01 | Q33: 0 | R33: =MIN(E33:L33) -> 786 | S33: =MAX(E33:L33) -> 842 | T33: =AVERAGE(E33:L33) -> 814.66667
B34: =B6 -> 4층 2-4반 | C34: =C6 -> 14:13 ~ 14:23 | D34: 3 | E34: 763 | G34: 819 | J34: 843 | Q34: 0 | R34: =MIN(E34:L34) -> 763 | S34: =MAX(E34:L34) -> 843 | T34: =AVERAGE(E34:L34) -> 808.33333
B35: =B7 -> 1층 (도제)회계실무실습실 | C35: =C7 -> 15:00 ~ 15:10 | D35: 3 | E35: 712 | G35: 736 | J35: 772 | R35: =MIN(E35:L35) -> 712 | S35: =MAX(E35:L35) -> 772 | T35: =AVERAGE(E35:L35) -> 740
B36: =B8 -> 0 | C36: =C8 -> 0 | D36: 3 | Q36: 0 | R36: =MIN(E36:L36) -> 0 | S36: =MAX(E36:L36) -> 0 | T36: =AVERAGE(E36:L36) -> #DIV/0! | U36: 유치원 수업중
B37: =B23 -> 급식시설 | C37: =C23 -> 14:46 ~ 14:56 | D37: 3 | E37: 512 | G37: 603 | J37: 582 | R37: =MIN(E37:L37) -> 512 | S37: =MAX(E37:L37) -> 603 | T37: =AVERAGE(E37:L37) -> 565.66667 | U37: 급식시설
A38: 일산화탄소 | B38: =B5 -> 5층 2-11반 | C38: =C5 -> 14:02 ~ 14:12 | D38: 3 | E38: 1.9 | G38: 1.92 | J38: 1.93 | O38: =O33 -> KEH-KW-01 | Q38: 0 | R38: =MIN(E38:L38) -> 1.9 | S38: =MAX(E38:L38) -> 1.93 | T38: =AVERAGE(E38:L38) -> 1.9166667
D39: 3 | Q39: 0 | R39: =MIN(E39:L39) -> 0 | S39: =MAX(E39:L39) -> 0 | T39: =AVERAGE(E39:L39) -> #DIV/0!
D40: 3 | Q40: 0 | R40: =MIN(E40:L40) -> 0 | S40: =MAX(E40:L40) -> 0 | T40: =AVERAGE(E40:L40) -> #DIV/0!
A41: NO2 | B41: =B5 -> 5층 2-11반 | C41: =C5 -> 14:02 ~ 14:12 | D41: 3 | E41: 0.019 | G41: 0.02 | J41: 0.021 | O41: =O38 -> KEH-KW-01 | Q41: 0 | R41: =MIN(E41:L41) -> 0.019 | S41: =MAX(E41:L41) -> 0.021 | T41: =AVERAGE(E41:L41) -> 0.02
D42: 3 | Q42: 0 | R42: =MIN(E42:L42) -> 0 | S42: =MAX(E42:L42) -> 0 | T42: =AVERAGE(E42:L42) -> #DIV/0! | U42: 지우지 말것!!!!
...

Sheet 보고서3
A1: 3. 측정지점별 측정결과 3-1. 학교시설에서의 공기질
A2: 측정 항목 | B2: 검사조건 | D2: 검사 | E2: 검사결과 | H2: 유지 기준 | I2: 평가결과 | J2: 측정기기 사양 | O2: 검사 방법 | P2: 비고
B3: 검사장소 | C3: 검사시간 | D3: 횟수 | E3: 최소 | F3: 최대 | G3: 평균 | J3: 제조 회사 | K3: 모델명 | L3: 제작일 | M3: 고유 번호 | N3: 성능 검사일
A5: 미세먼지 PM10 (㎍/㎥) | B5: ='입력2(측정)'!B19 -> 5층 2-11반 | C5: ='입력2(측정)'!C19 -> 14:02 ~ 14:12 | D5: ='입력2(측정)'!D19 -> 5 | E5: ='입력2(측정)'!R19 -> 11 | F5: ='입력2(측정)'!S19 -> 13 | G5: ='입력2(측정)'!T19 -> 11.8 | H5: 75 ㎍/㎥ 이하 | I5: =IF(G5>75,"부적합","적합") -> 적합 | J5: 케이웨더(주) | K5: IAQ-SC | L5: 26.02.27 | M5: ISCFW2500037 | N5: 26.03.03.~ 26.03.06. | O5: 광산 란법
B6: ='입력2(측정)'!B20 -> 4층 2-4반 | C6: ='입력2(측정)'!C20 -> 14:13 ~ 14:23 | D6: ='입력2(측정)'!D20 -> 5 | E6: ='입력2(측정)'!R20 -> 16 | F6: ='입력2(측정)'!S20 -> 18 | G6: ='입력2(측정)'!T20 -> 16.8 | H6: 75 ㎍/㎥ 이하 | I6: =IF(G6>75,"부적합","적합") -> 적합
B7: ='입력2(측정)'!B21 -> 1층 (도제)회계실무실습실 | C7: ='입력2(측정)'!C21 -> 15:00 ~ 15:10 | D7: ='입력2(측정)'!D21 -> 5 | E7: ='입력2(측정)'!R21 -> 13 | F7: ='입력2(측정)'!S21 -> 15 | G7: ='입력2(측정)'!T21 -> 14.2 | H7: 75 ㎍/㎥ 이하 | I7: =IF(G7>75,"부적합","적합") -> 적합
B8: - | C8: - | D8: - | E8: - | F8: - | G8: - | H8: - | I8: -
B9: ='입력2(측정)'!B23 -> 급식시설 | C9: ='입력2(측정)'!C23 -> 14:46 ~ 14:56 | D9: ='입력2(측정)'!D23 -> 5 | E9: ='입력2(측정)'!R23 -> 14 | F9: ='입력2(측정)'!S23 -> 18 | G9: ='입력2(측정)'!T23 -> 15.8 | H9: 75 ㎍/㎥ 이하 | I9: =IF(G9>75,"부적합","적합") -> 적합
B10: ='입력2(측정)'!B24 -> 체육관 | C10: ='입력2(측정)'!C24 -> 13:38 ~ 13:48 | D10: ='입력2(측정)'!D24 -> 10 | E10: ='입력2(측정)'!R24 -> 23 | F10: ='입력2(측정)'!S24 -> 27 | G10: ='입력2(측정)'!T24 -> 24.9 | H10: 150 ㎍/㎥ 이하 | I10: =IF(G10>150,"부적합","적합") -> 적합
B11: - | C11: - | D11: - | E11: - | F11: - | G11: - | H11: - | I11: -
A12: 초미세먼지 PM2.5 (㎍/㎥) | B12: ='입력2(측정)'!B28 -> 5층 2-11반 | C12: ='입력2(측정)'!C28 -> 14:02 ~ 14:12 | D12: ='입력2(측정)'!D28 -> 5 | E12: ='입력2(측정)'!R28 -> 10 | F12: ='입력2(측정)'!S28 -> 12 | G12: ='입력2(측정)'!T28 -> 10.8 | H12: 35 ㎍/㎥ 이하 | I12: =IF(G12>35,"부적합","적합") -> 적합 | J12: 케이웨더(주) | K12: IAQ-SC | L12: 26.02.27 | M12: ISCFW2500037 | N12: 26.03.03.~ 26.03.06. | O12: 광산 란법
B13: ='입력2(측정)'!B29 -> 4층 2-4반 | C13: ='입력2(측정)'!C29 -> 14:13 ~ 14:23 | D13: ='입력2(측정)'!D29 -> 5 | E13: ='입력2(측정)'!R29 -> 15 | F13: ='입력2(측정)'!S29 -> 17 | G13: ='입력2(측정)'!T29 -> 15.8 | H13: 35 ㎍/㎥ 이하 | I13: =IF(G13>35,"부적합","적합") -> 적합
B14: ='입력2(측정)'!B30 -> 1층 (도제)회계실무실습실 | C14: ='입력2(측정)'!C30 -> 15:00 ~ 15:10 | D14: ='입력2(측정)'!D30 -> 5 | E14: ='입력2(측정)'!R30 -> 12 | F14: ='입력2(측정)'!S30 -> 14 | G14: ='입력2(측정)'!T30 -> 13.2 | H14: 35 ㎍/㎥ 이하 | I14: =IF(G14>35,"부적합","적합") -> 적합
B15: - | C15: - | D15: - | E15: - | F15: - | G15: - | H15: - | I15: -
B16: ='입력2(측정)'!B32 -> 급식시설 | C16: ='입력2(측정)'!C32 -> 14:46 ~ 14:56 | D16: ='입력2(측정)'!D32 -> 5 | E16: ='입력2(측정)'!R32 -> 13 | F16: ='입력2(측정)'!S32 -> 17 | G16: ='입력2(측정)'!T32 -> 14.8 | H16: 35 ㎍/㎥ 이하 | I16: =IF(G16>35,"부적합","적합") -> 적합
A17: 이산화탄소 CO2 (ppm) | B17: ='입력2(측정)'!B33 -> 5층 2-11반 | C17: ='입력2(측정)'!C33 -> 14:02 ~ 14:12 | D17: ='입력2(측정)'!D33 -> 3 | E17: ='입력2(측정)'!R33 -> 786 | F17: ='입력2(측정)'!S33 -> 842 | G17: ='입력2(측정)'!T33 -> 814.66667 | H17: 1000 ppm 이하 | I17: =IF(G17>1000,"부적합","적합") -> 적합 | J17: 케이웨더(주) | K17: IAQ-SC | L17: 26.02.27 | M17: ISCFW2500037 | N17: 26.03.03.~ 26.03.06. | O17: 비분산적외선법
B18: ='입력2(측정)'!B34 -> 4층 2-4반 | C18: ='입력2(측정)'!C34 -> 14:13 ~ 14:23 | D18: ='입력2(측정)'!D34 -> 3 | E18: ='입력2(측정)'!R34 -> 763 | F18: ='입력2(측정)'!S34 -> 843 | G18: ='입력2(측정)'!T34 -> 808.33333 | H18: 1000 ppm 이하 | I18: =IF(G18>1000,"부적합","적합") -> 적합
B19: ='입력2(측정)'!B35 -> 1층 (도제)회계실무실습실 | C19: ='입력2(측정)'!C35 -> 15:00 ~ 15:10 | D19: ='입력2(측정)'!D35 -> 3 | E19: ='입력2(측정)'!R35 -> 712 | F19: ='입력2(측정)'!S35 -> 772 | G19: ='입력2(측정)'!T35 -> 740 | H19: 1000 ppm 이하 | I19: =IF(G19>1000,"부적합","적합") -> 적합
B20: - | C20: - | D20: - | E20: - | F20: - | G20: - | H20: - | I20: -
B21: ='입력2(측정)'!B37 -> 급식시설 | C21: ='입력2(측정)'!C37 -> 14:46 ~ 14:56 | D21: ='입력2(측정)'!D36 -> 3 | E21: ='입력2(측정)'!R37 -> 512 | F21: ='입력2(측정)'!S37 -> 603 | G21: ='입력2(측정)'!T37 -> 565.66667 | H21: 1000 ppm 이하 | I21: =IF(G21>1000,"부적합","적합") -> 적합
B22: ='입력2(측정)'!B38 -> 5층 2-11반 | C22: ='입력2(측정)'!C25 -> 0 | D22: ='입력2(측정)'!D37 -> 3 | E22: ='입력2(측정)'!R37 -> 512 | F22: ='입력2(측정)'!S37 -> 603 | G22: ='입력2(측정)'!T38 -> 1.9166667 | H22: 1000 ppm 이하 | I22: =IF(G22>1000,"부적합","적합") -> 적합
A23: 포름알데하이드 HCHO (직독식) | B23: ='입력2(측정)'!B67 -> 5층 1-9반 | C23: ='입력2(측정)'!C67 -> 13:03 ~ 13:13 | D23: ='입력2(측정)'!D67 -> 3 | E23: ='입력2(측정)'!R67 -> 27 | F23: ='입력2(측정)'!S67 -> 33 | G23: ='입력2(측정)'!T67 -> 30.666667 | H23: 80 ug/㎥ 이하 | I23: =IF(G23>80,"부적합","적합") -> 적합 | J23: 케이웨더(주) | K23: IAQ-SC | L23: 26.02.27 | M23: ISCFW2500037 | N23: 26.03.03.~ 26.03.06. | O23: 전기화학식
B24: ='입력2(측정)'!B68 -> 4층 1-7반 | C24: ='입력2(측정)'!C68 -> 13:15 ~ 13:25 | D24: ='입력2(측정)'!D68 -> 3 | E24: ='입력2(측정)'!R68 -> 40 | F24: ='입력2(측정)'!S68 -> 45 | G24: ='입력2(측정)'!T68 -> 43 | H24: 80 ug/㎥ 이하 | I24: =IF(G24>80,"부적합","적합") -> 적합
B25: ='입력2(측정)'!B69 -> 2층 (도제)세무실무실습실 | C25: ='입력2(측정)'!C69 -> 13:26 ~ 13:36 | D25: ='입력2(측정)'!D69 -> 3 | E25: ='입력2(측정)'!R69 -> 32 | F25: ='입력2(측정)'!S69 -> 36 | G25: ='입력2(측정)'!T69 -> 34 | H25: 80 ug/㎥ 이하 | I25: =IF(G25>80,"부적합","적합") -> 적합
B26: - | C26: - | D26: - | E26: - | F26: - | G26: - | H26: - | I26: -
B27: ='입력2(측정)'!B71 -> 급식시설 | C27: ='입력2(측정)'!C71 -> 14:46 ~ 14:56 | D27: ='입력2(측정)'!D71 -> 3 | E27: ='입력2(측정)'!R71 -> 59 | F27: ='입력2(측정)'!S71 -> 63 | G27: ='입력2(측정)'!T71 -> 60.666667 | H27: 80 ug/㎥ 이하 | I27: =IF(G27>80,"부적합","적합") -> 적합
A28: 포름알데하이드 HCHO ( DNPH) | B28: ='입력2(측정)'!B112 -> 1층 1-12반 | C28: ='입력2(측정)'!C112 -> 13:12 ~ 14:12 | D28: 2 | E28: ='입력2(측정)'!R112 -> 14.303685 | F28: ='입력2(측정)'!S112 -> 16.788362 | G28: ='입력2(측정)'!T112 -> 15.546023 | H28: 80 ug/㎥ 이하 | I28: =IF(G28>80,"부적합","적합") -> 적합 | J28: - | K28: - | L28: - | M28: - | N28: - | O28: -
B29: ='입력2(측정)'!B113 -> 2층 2-12반 | C29: ='입력2(측정)'!C113 -> 14:05 ~ 15:05 | D29: 2 | E29: ='입력2(측정)'!R113 -> 7.7332291 | F29: ='입력2(측정)'!S113 -> 9.5305231 | G29: ='입력2(측정)'!T113 -> 8.6318761 | H29: 80 ug/㎥ 이하 | I29: =IF(G29>80,"부적합","적합") -> 적합
B30: ='입력2(측정)'!B114 -> 1층 스포티존 | C30: ='입력2(측정)'!C114 -> 13:00 ~ 14:00 | D30: 2 | E30: ='입력2(측정)'!R114 -> 26.227584 | F30: ='입력2(측정)'!S114 -> 28.577047 | G30: ='입력2(측정)'!T114 -> 27.402316 | H30: 80 ug/㎥ 이하 | I30: =IF(G30>80,"부적합","적합") -> 적합
A31: 총부유 세균 (CFU/㎥) | B31: ='입력2(측정)'!B46 -> 5층 2-11반 | C31: ='입력2(측정)'!C46 -> 14:02 ~ 14:12 | D31: 1 | E31: - | F31: - | G31: ='입력2(측정)'!Z46 -> 80.852563 | H31: 800 CFU/㎥ 이하 | I31: =IF(G31>800,"부적합","적합") -> 적합 | J31: A.P. BUCK | K31: BIO-CULTURE | L31: 26.04.17 | M31: C103640 | N31: 26.03.03 | O31: 충돌법
B32: ='입력2(측정)'!B47 -> 4층 2-4반 | C32: ='입력2(측정)'!C47 -> 14:13 ~ 14:23 | D32: 1 | E32: - | F32: - | G32: ='입력2(측정)'!Z47 -> 242.16029 | H32: 800 CFU/㎥ 이하 | I32: =IF(G32>800,"부적합","적합") -> 적합
B33: ='입력2(측정)'!B48 -> 1층 (도제)회계실무실습실 | C33: ='입력2(측정)'!C48 -> 15:00 ~ 15:10 | D33: 1 | E33: - | F33: - | G33: ='입력2(측정)'!Z48 -> 30.304173 | H33: 800 CFU/㎥ 이하 | I33: =IF(G33>800,"부적합","적합") -> 적합
B34: - | C34: - | D34: - | E34: - | F34: - | G34: - | H34: - | I34: -
A35: 낙하 세균 (CFU/실) | B35: ='입력2(측정)'!B52 -> 급식시설 | C35: ='입력2(측정)'!C52 -> 14:46 ~ 14:56 | D35: ='입력2(측정)'!D52 -> 3 | E35: ='입력2(측정)'!R52 -> 0 | F35: ='입력2(측정)'!S52 -> 0 | G35: ='입력2(측정)'!T52 -> 0 | H35: 10 CFU/실 이하 | I35: =IF(G35>10,"부적합","적합") -> 적합 | J35: HANGANG Prepared Media | K35: 한천배지 | L35: 26.03.03 | M35: - | N35: - | O35: 낙하세균법
B36: ='입력2(측정)'!B53 -> 보건실 | C36: ='입력2(측정)'!C53 -> 13:49 ~ 13:59 | D36: ='입력2(측정)'!D53 -> 3 | E36: ='입력2(측정)'!R53 -> 0 | F36: ='입력2(측정)'!S53 -> 1 | G36: ='입력2(측정)'!T53 -> 0.66666667 | H36: 10 CFU/실 이하 | I36: =IF(G36>10,"부적합","적합") -> 적합
B37: - | C37: - | D37: - | E37: - | F37: - | G37: - | H37: - | I37: -
B38: - | C38: - | D38: - | E38: - | F38: - | G38: - | H38: - | I38: -
A39: 일산화탄소 CO | B39: ='입력2(측정)'!B38 -> 5층 2-11반 | C39: ='입력2(측정)'!C38 -> 14:02 ~ 14:12 | D39: 3 | E39: ='입력2(측정)'!R38 -> 1.9 | F39: ='입력2(측정)'!S38 -> 1.93 | G39: ='입력2(측정)'!T38 -> 1.9166667 | H39: 10 ppm 이하 | I39: =IF(G39>10,"부적합","적합") -> 적합 | J39: 케이웨더(주) | K39: IAQ-SC | L39: 26.02.27 | M39: ISCFW2500037 | N39: 26.03.03.~ 26.03.06. | O39: 전기화학식
B40: - | C40: - | D40: - | E40: - | F40: - | G40: - | H40: - | I40: -
B41: - | C41: - | D41: - | E41: - | F41: - | G41: - | H41: - | I41: -
...

Sheet 측정사진
B1: 측정사진
B12: 강당 | G12: 급식시설
B23: 보건실 | G23: 빈교실 일반교실
B34: 수업중 일반교실 | G34: 특별점검 1-1반

Sheet 실내공기질 측정기록부
B2: [별지 제21호서식]
B3: 실내공기질 측정기록부
B4: ① 의 뢰 인 | C4: 상호(기관명) | D4: ='입력1(학교시설명 등 기본사항 입력) 보고서1,2'!C2 -> 평촌경영고등학교 | G4: ② 의뢰 내용 | H4: 측정용도 | I4: 자가측정용
C5: 소재지(주소) | D5: ='입력1(학교시설명 등 기본사항 입력) 보고서1,2'!C3 -> 경기도 안양시 동안구 학의로 186 | H5: 시설명 | I5: 학교시설
C6: 대표자 (의뢰인) | D6: ='입력1(학교시설명 등 기본사항 입력) 보고서1,2'!H2 -> 손옥기 | H6: 규모 | I6: -
C7: 관리책임자 | D7: 김신영 | H7: 의뢰항목 | I7: 정기점검
B8: ② 시료채취 | C8: 측정지점 | D8: 온도 (°C) 기준 (18~28) | E8: 습도 (%) (30~80) | F8: 환기 | G8: O₃(오존) (0.06ppm) | H8: 소음 (dB) (55 이하) | I8: 조도
I9: 조도 칠판면(lux) (300 이상) | J9: 비(최대:최소) (3:1) | K9: 책상면(lux) (300 이상) | L9: 비(최대:최소) (3:1)
C10: =보고서3!B95 -> 5층 2-11반 | D10: =보고서3!G95 -> 25.5 | E10: =보고서3!G102 -> 41.39 | F10: =보고서3!G113 -> 57.04408 | G10: - | H10: - | I10: - | J10: - | K10: - | L10: -
C11: =보고서3!B96 -> 4층 2-4반 | D11: =보고서3!G96 -> 25.1 | E11: =보고서3!G103 -> 45.666667 | F11: =보고서3!G114 -> 57.996485 | G11: - | H11: - | I11: - | J11: - | K11: - | L11: -
C12: =보고서3!B97 -> 1층 (도제)회계실무실습실 | D12: =보고서3!G97 -> 25.733333 | E12: =보고서3!G104 -> 51.7 | F12: =보고서3!G115 -> 70.73955 | G12: - | H12: - | I12: - | J12: - | K12: - | L12: -
C13: =보고서3!B98 -> - | D13: =보고서3!G98 -> - | E13: =보고서3!G105 -> - | F13: =보고서3!G116 -> - | G13: - | H13: - | I13: - | J13: - | K13: -
C14: ='입력2(측정)'!B68 -> 4층 1-7반 | D14: =보고서3!G99 -> - | E14: =보고서3!G106 -> - | F14: ='입력2(측정)'!#REF! -> #REF! | G14: - | H14: - | I14: ='입력2(측정)'!T78 -> 504.55556 | J14: ='입력2(측정)'!T94 -> 1.3302108 | K14: ='입력2(측정)'!T86 -> 773.55556 | L14: ='입력2(측정)'!T102 -> 1.3004354
C15: =보고서3!B23 -> 5층 1-9반 | D15: - | E15: - | F15: - | G15: - | H15: =보고서3!G109 -> 47.6 | I15: =보고서3!G79 -> 405.22222 | J15: =보고서3!G87 -> 1.4401198 | K15: =보고서3!G83 -> 839.77778 | L15: =보고서3!G91 -> 1.3019126
C16: =보고서3!B24 -> 4층 1-7반 | D16: - | E16: - | F16: - | G16: - | H16: =보고서3!G110 -> 48.95 | I16: =보고서3!G80 -> 504.55556 | J16: =보고서3!G88 -> 1.3302108 | K16: =보고서3!G84 -> 773.55556 | L16: =보고서3!G92 -> 1.3004354
C17: =보고서3!B25 -> 2층 (도제)세무실무실습실 | D17: - | E17: - | F17: - | G17: - | H17: =보고서3!G111 -> 50.5 | I17: =보고서3!G81 -> 745.33333 | J17: =보고서3!G89 -> 1.4591503 | K17: =보고서3!G85 -> 720.11111 | L17: =보고서3!G93 -> 1.3582555
C18: =보고서3!B26 -> - | D18: - | E18: - | F18: - | G18: - | H18: =보고서3!G112 -> - | I18: =보고서3!G82 -> - | J18: =보고서3!G90 -> - | K18: =보고서3!G86 -> - | L18: =보고서3!G94 -> -
C19: =보고서3!B53 -> 교무실 | D19: - | E19: - | F19: - | G19: =보고서3!G53 -> 0.011666667 | H19: - | I19: - | J19: - | K19: - | L19: -
C20: 채취자 의견 | D20: 특이사항 없음
C21: 시료채취일 | D21: ='입력1(학교시설명 등 기본사항 입력) 보고서1,2'!C13 -> 2026.06.10 | G21: 시료채취자 | J21: 박정식 (인)
B22: ④ 측정 분석 결과 | C22: 측정지점 | D22: 측정시간 | E22: PM10 (75µg/㎥) | F22: PM10 (150µg/㎥) | G22: PM2.5 (35µg/㎥) | H22: CO2 (1,000ppm) | I22: CO (10ppm) | J22: NO2 (0.05ppm) | K22: 총부유세균 (800CFU/㎥) | L22: HCHO (80µg/㎥)
C23: =보고서3!B5 -> 5층 2-11반 | D23: =보고서3!C5 -> 14:02 ~ 14:12 | E23: =보고서3!G5 -> 11.8 | F23: - | G23: =보고서3!G12 -> 10.8 | H23: =보고서3!G17 -> 814.66667 | I23: =보고서3!G39 -> 1.9166667 | J23: =보고서3!G42 -> 0.02 | K23: =보고서3!G31 -> 80.852563 | L23: -
C24: =보고서3!B6 -> 4층 2-4반 | D24: =보고서3!C6 -> 14:13 ~ 14:23 | E24: =보고서3!G6 -> 16.8 | F24: - | G24: =보고서3!G13 -> 15.8 | H24: =보고서3!G18 -> 808.33333 | I24: - | J24: - | K24: =보고서3!G32 -> 242.16029 | L24: -
C25: =보고서3!B7 -> 1층 (도제)회계실무실습실 | D25: =보고서3!C7 -> 15:00 ~ 15:10 | E25: =보고서3!G7 -> 14.2 | F25: - | G25: =보고서3!G14 -> 13.2 | H25: =보고서3!G19 -> 740 | I25: - | J25: - | K25: =보고서3!G33 -> 30.304173 | L25: -
C26: =보고서3!B8 -> - | D26: =보고서3!C8 -> - | E26: =보고서3!G8 -> - | F26: - | G26: =보고서3!G15 -> - | H26: =보고서3!G20 -> - | I26: - | J26: - | K26: =보고서3!G34 -> - | L26: -
C27: =보고서3!B10 -> 체육관 | D27: =보고서3!C10 -> 13:38 ~ 13:48 | E27: - | F27: =보고서3!G10 -> 24.9 | G27: - | H27: - | I27: - | J27: - | K27: - | L27: -
C28: =보고서3!B11 -> - | D28: =보고서3!C11 -> - | E28: - | F28: =보고서3!G11 -> - | G28: - | H28: - | I28: - | J28: - | K28: - | L28: -
C29: =보고서3!B23 -> 5층 1-9반 | D29: =보고서3!C23 -> 13:03 ~ 13:13 | E29: - | F29: - | G29: - | H29: - | I29: - | J29: - | K29: - | L29: =보고서3!G23 -> 30.666667
C30: =보고서3!B24 -> 4층 1-7반 | D30: =보고서3!C24 -> 13:15 ~ 13:25 | E30: - | F30: - | G30: - | H30: - | I30: - | J30: - | K30: - | L30: =보고서3!G24 -> 43
C31: =보고서3!B25 -> 2층 (도제)세무실무실습실 | D31: =보고서3!C25 -> 13:26 ~ 13:36 | E31: - | F31: - | G31: - | H31: - | I31: - | J31: - | K31: - | L31: =보고서3!G25 -> 34
C32: =보고서3!B26 -> - | D32: =보고서3!C26 -> - | E32: - | F32: - | G32: - | H32: - | I32: - | J32: - | K32: - | L32: =보고서3!G26 -> -
C33: =보고서3!B9 -> 급식시설 | D33: =보고서3!C9 -> 14:46 ~ 14:56 | E33: =보고서3!G9 -> 15.8 | F33: - | G33: =보고서3!G16 -> 14.8 | H33: =보고서3!G21 -> 565.66667 | I33: - | J33: - | K33: - | L33: =보고서3!G27 -> 60.666667
C34: 측정지점 | D34: 측정시간 | E34: 낙하세균 (10CFU/실) | F34: 진드기 (100마리/㎡) | G34: Rn (148Bq/㎥) | I34: 석면 (0.01개/cc) | K34: -
C35: =보고서3!B35 -> 급식시설 | D35: =보고서3!C35 -> 14:46 ~ 14:56 | E35: =보고서3!G35 -> 0 | F35: - | G35: - | I35: ='입력2(측정)'!E57 -> 0 | K35: -
C36: =보고서3!B36 -> 보건실 | D36: =보고서3!C36 -> 13:49 ~ 13:59 | E36: =보고서3!G36 -> 0.66666667 | F36: =보고서3!G56 -> 20이하 | G36: - | I36: ='입력2(측정)'!E58 -> 0 | K36: -
D37: =보고서3!C45 -> 2026-03-30~ 2026-06-29 | E37: - | F37: - | G37: =보고서3!G45 -> - | I37: =보고서3!G47 -> - | K37: -
C38: =보고서3!B48 -> - | D38: =보고서3!C48 -> - | E38: - | F38: - | G38: - | I38: =보고서3!G48 -> - | K38: -
C39: =보고서3!B49 -> - | D39: =보고서3!C49 -> - | E39: - | F39: - | G39: - | I39: =보고서3!G49 -> - | K39: -
C40: =보고서3!B50 -> - | D40: =보고서3!C50 -> - | E40: - | F40: - | G40: - | I40: =보고서3!G50 -> - | K40: -
C41: 측정지점 | D41: 측정시간 | E41: HCHO (80µg/㎥) | F41: TVOC (400µg/㎥) | G41: 벤젠 (30µg/㎥) | H41: 톨루엔 (1,000µg/㎥) | I41: 에틸벤젠 (350µg/㎥) | J41: 자일렌 (700µg/㎥) | K41: 스티렌 (300µg/㎥) | L41: -
...

Sheet 시료인계서
A3: 시료접수 및 인계서
A4: 시료채취일시 | C4: ='입력1(학교시설명 등 기본사항 입력) 보고서1,2'!C13 -> 2026.06.10 | H4: HCHO | I4: 포름알데하이드
A5: 대상시설(시료명) | C5: ='입력1(학교시설명 등 기본사항 입력) 보고서1,2'!C2 -> 평촌경영고등학교 | H5: VOC | I5: 총휘발성유기화합물
A6: 시험항목 | C6: HCHO, VOC, BBA, NBA | H6: PM2.5 | I6: 초미세먼지
A7: 시료 인계 사항 | B7: 시험항목 | C7: 시설명 | D7: 시료 구분명 | E7: 시료번호 | F7: 흡착관 번호 (TVOC측정시) | G7: 시료번호 | H7: PM10 | I7: 미세먼지
B8: 포름알데하이드 | C8: =$C$5 -> 평촌경영고등학교 | D8: HCHO | E8: 1 | G8: =CONCATENATE(D8,"-",E8,"-",F8) -> HCHO-1- | H8: BMD | I8: 곰팡이
B9: 포름알데하이드 | C9: =$C$5 -> 평촌경영고등학교 | D9: HCHO | E9: 2 | G9: =CONCATENATE(D9,"-",E9,"-",F9) -> HCHO-2- | H9: BBA | I9: 부유세균
B10: 포름알데하이드 | C10: =$C$5 -> 평촌경영고등학교 | D10: HCHO | E10: 3 | G10: =CONCATENATE(D10,"-",E10,"-",F10) -> HCHO-3- | H10: NBA | I10: 낙하세균
B11: 포름알데하이드 | C11: =$C$5 -> 평촌경영고등학교 | D11: HCHO | E11: 4 | G11: =CONCATENATE(D11,"-",E11,"-",F11) -> HCHO-4- | H11: AB | I11: 석면
B12: 포름알데하이드 | C12: =$C$5 -> 평촌경영고등학교 | D12: HCHO | E12: 5 | G12: =CONCATENATE(D12,"-",E12,"-",F12) -> HCHO-5-
B13: 포름알데하이드 | C13: =$C$5 -> 평촌경영고등학교 | D13: HCHO | E13: 6 | G13: =CONCATENATE(D13,"-",E13,"-",F13) -> HCHO-6-
B14: 총휘발성유기화합물 | C14: =$C$5 -> 평촌경영고등학교 | D14: VOC | E14: 1 | F14: A10741 | G14: =CONCATENATE(D14,"-",E14,"-",F14) -> VOC-1-A10741
B15: 총휘발성유기화합물 | C15: =$C$5 -> 평촌경영고등학교 | D15: VOC | E15: 2 | F15: A11429 | G15: =CONCATENATE(D15,"-",E15,"-",F15) -> VOC-2-A11429
B16: 총휘발성유기화합물 | C16: =$C$5 -> 평촌경영고등학교 | D16: VOC | E16: 3 | F16: A11416 | G16: =CONCATENATE(D16,"-",E16,"-",F16) -> VOC-3-A11416
B17: 총휘발성유기화합물 | C17: =$C$5 -> 평촌경영고등학교 | D17: VOC | E17: 4 | F17: A11417 | G17: =CONCATENATE(D17,"-",E17,"-",F17) -> VOC-4-A11417
B18: 총휘발성유기화합물 | C18: =$C$5 -> 평촌경영고등학교 | D18: VOC | E18: 5 | F18: A08800 | G18: =CONCATENATE(D18,"-",E18,"-",F18) -> VOC-5-A08800
B19: 총휘발성유기화합물 | C19: =$C$5 -> 평촌경영고등학교 | D19: VOC | E19: 6 | F19: A11412 | G19: =CONCATENATE(D19,"-",E19,"-",F19) -> VOC-6-A11412
B20: 부유세균 | C20: =$C$5 -> 평촌경영고등학교 | D20: BBA | E20: 1 | G20: =CONCATENATE(D20,"-",E20,"-",F20) -> BBA-1-
B21: 부유세균 | C21: =$C$5 -> 평촌경영고등학교 | D21: BBA | E21: 2 | G21: =CONCATENATE(D21,"-",E21,"-",F21) -> BBA-2-
B22: 부유세균 | C22: =$C$5 -> 평촌경영고등학교 | D22: BBA | E22: 3 | G22: =CONCATENATE(D22,"-",E22,"-",F22) -> BBA-3-
B23: 낙하세균 | C23: =$C$5 -> 평촌경영고등학교 | D23: NBA | E23: 1 | G23: =CONCATENATE(D23,"-",E23,"-",F23) -> NBA-1-
B24: 낙하세균 | C24: =$C$5 -> 평촌경영고등학교 | D24: NBA | E24: 2 | G24: =CONCATENATE(D24,"-",E24,"-",F24) -> NBA-2-
B25: 낙하세균 | C25: =$C$5 -> 평촌경영고등학교 | D25: NBA | E25: 3 | G25: =CONCATENATE(D25,"-",E25,"-",F25) -> NBA-3-
B26: 낙하세균 | C26: =$C$5 -> 평촌경영고등학교 | D26: NBA | E26: 4 | G26: =CONCATENATE(D26,"-",E26,"-",F26) -> NBA-4-
B27: 낙하세균 | C27: =$C$5 -> 평촌경영고등학교 | D27: NBA | E27: 5 | G27: =CONCATENATE(D27,"-",E27,"-",F27) -> NBA-5-
B28: 낙하세균 | C28: =$C$5 -> 평촌경영고등학교 | D28: NBA | E28: 6 | G28: =CONCATENATE(D28,"-",E28,"-",F28) -> NBA-6-
C29: =$C$5 -> 평촌경영고등학교 | G29: =CONCATENATE(D29,"-",E29,"-",F29) -> --
C30: =$C$5 -> 평촌경영고등학교 | G30: =CONCATENATE(D30,"-",E30,"-",F30) -> -- | J30: HCHO
C31: =$C$5 -> 평촌경영고등학교 | G31: =CONCATENATE(D31,"-",E31,"-",F31) -> -- | J31: VOC
C32: =$C$5 -> 평촌경영고등학교 | G32: =CONCATENATE(D32,"-",E32,"-",F32) -> -- | J32: PM2.5
C33: =$C$5 -> 평촌경영고등학교 | G33: =CONCATENATE(D33,"-",E33,"-",F33) -> -- | J33: PM10
A34: 시료접수일 | B34: 46183 | J34: BMD
A35: 인계자 | B35: 박정식 | F35: (서명 또는 인) | J35: BBA
A36: 인수자 | B36: 유재혁 | F36: (서명 또는 인) | J36: NBA
A37: 기타 | J37: JIN
A38: *첨부서류 1. 시료채취기록부
A43: KEH-QPI서식-17-01 (Rev. 00) A4(210×297mm)

Sheet 시료번호 입렵
A1: 채취 시료 정보
A3: 측정일 | B3: 측정자 | C3: 시설명 | D3: 측정위치 | E3: 측정항목 | F3: 시료번호 | H3: 비고
F4: 시설명 | G4: 시료번호
A5: =시료인계서!$C$4 -> 2026.06.10 | B5: ='입력1(학교시설명 등 기본사항 입력) 보고서1,2'!$I$15 -> 박정식 | C5: =시료인계서!$C$5 -> 평촌경영고등학교 | D5: 1층 1-12 | E5: =시료인계서!$B$8 -> 포름알데하이드 | F5: =시료인계서!C8 -> 평촌경영고등학교 | G5: =시료인계서!G8 -> HCHO-1-
A6: =시료인계서!$C$4 -> 2026.06.10 | B6: ='입력1(학교시설명 등 기본사항 입력) 보고서1,2'!$I$15 -> 박정식 | C6: =시료인계서!$C$5 -> 평촌경영고등학교 | D6: 1층 1-12 | E6: =시료인계서!$B$9 -> 포름알데하이드 | F6: =시료인계서!C9 -> 평촌경영고등학교 | G6: =시료인계서!G9 -> HCHO-2-
A7: =시료인계서!$C$4 -> 2026.06.10 | B7: ='입력1(학교시설명 등 기본사항 입력) 보고서1,2'!$I$15 -> 박정식 | C7: =시료인계서!$C$5 -> 평촌경영고등학교 | D7: 1층 2-12 | E7: =시료인계서!$B$10 -> 포름알데하이드 | F7: =시료인계서!C10 -> 평촌경영고등학교 | G7: =시료인계서!G10 -> HCHO-3-
A8: =시료인계서!$C$4 -> 2026.06.10 | B8: ='입력1(학교시설명 등 기본사항 입력) 보고서1,2'!$I$15 -> 박정식 | C8: =시료인계서!$C$5 -> 평촌경영고등학교 | D8: 1층 2-12 | E8: =시료인계서!$B$11 -> 포름알데하이드 | F8: =시료인계서!C11 -> 평촌경영고등학교 | G8: =시료인계서!G11 -> HCHO-4-
A9: =시료인계서!$C$4 -> 2026.06.10 | B9: ='입력1(학교시설명 등 기본사항 입력) 보고서1,2'!$I$15 -> 박정식 | C9: =시료인계서!$C$5 -> 평촌경영고등학교 | D9: 1층 스포티존 | E9: =시료인계서!$B$12 -> 포름알데하이드 | F9: =시료인계서!C12 -> 평촌경영고등학교 | G9: =시료인계서!G12 -> HCHO-5-
A10: =시료인계서!$C$4 -> 2026.06.10 | B10: ='입력1(학교시설명 등 기본사항 입력) 보고서1,2'!$I$15 -> 박정식 | C10: =시료인계서!$C$5 -> 평촌경영고등학교 | D10: 1층 스포티존 | E10: =시료인계서!$B$13 -> 포름알데하이드 | F10: =시료인계서!C13 -> 평촌경영고등학교 | G10: =시료인계서!G13 -> HCHO-6-
A11: =시료인계서!$C$4 -> 2026.06.10 | B11: ='입력1(학교시설명 등 기본사항 입력) 보고서1,2'!$I$15 -> 박정식 | C11: =시료인계서!$C$5 -> 평촌경영고등학교 | D11: 1층 1-12 | E11: =시료인계서!$B$14 -> 총휘발성유기화합물 | F11: =시료인계서!C14 -> 평촌경영고등학교 | G11: =시료인계서!G14 -> VOC-1-A10741
A12: =시료인계서!$C$4 -> 2026.06.10 | B12: ='입력1(학교시설명 등 기본사항 입력) 보고서1,2'!$I$15 -> 박정식 | C12: =시료인계서!$C$5 -> 평촌경영고등학교 | D12: 1층 1-12 | E12: =시료인계서!$B$15 -> 총휘발성유기화합물 | F12: =시료인계서!C15 -> 평촌경영고등학교 | G12: =시료인계서!G15 -> VOC-2-A11429
A13: =시료인계서!$C$4 -> 2026.06.10 | B13: ='입력1(학교시설명 등 기본사항 입력) 보고서1,2'!$I$15 -> 박정식 | C13: =시료인계서!$C$5 -> 평촌경영고등학교 | D13: 1층 2-12 | E13: =시료인계서!$B$16 -> 총휘발성유기화합물 | F13: =시료인계서!C16 -> 평촌경영고등학교 | G13: =시료인계서!G16 -> VOC-3-A11416
A14: =시료인계서!$C$4 -> 2026.06.10 | B14: ='입력1(학교시설명 등 기본사항 입력) 보고서1,2'!$I$15 -> 박정식 | C14: =시료인계서!$C$5 -> 평촌경영고등학교 | D14: 1층 2-12 | E14: =시료인계서!$B$17 -> 총휘발성유기화합물 | F14: =시료인계서!C17 -> 평촌경영고등학교 | G14: =시료인계서!G17 -> VOC-4-A11417
A15: =시료인계서!$C$4 -> 2026.06.10 | B15: ='입력1(학교시설명 등 기본사항 입력) 보고서1,2'!$I$15 -> 박정식 | C15: =시료인계서!$C$5 -> 평촌경영고등학교 | D15: 1층 스포티존 | E15: =시료인계서!$B$18 -> 총휘발성유기화합물 | F15: =시료인계서!C18 -> 평촌경영고등학교 | G15: =시료인계서!G18 -> VOC-5-A08800
A16: =시료인계서!$C$4 -> 2026.06.10 | B16: ='입력1(학교시설명 등 기본사항 입력) 보고서1,2'!$I$15 -> 박정식 | C16: =시료인계서!$C$5 -> 평촌경영고등학교 | D16: 1층 스포티존 | E16: =시료인계서!$B$19 -> 총휘발성유기화합물 | F16: =시료인계서!C19 -> 평촌경영고등학교 | G16: =시료인계서!G19 -> VOC-6-A11412
A17: =시료인계서!$C$4 -> 2026.06.10 | B17: ='입력1(학교시설명 등 기본사항 입력) 보고서1,2'!$I$15 -> 박정식 | C17: =시료인계서!$C$5 -> 평촌경영고등학교 | D17: 5층 2-11 | E17: =시료인계서!$B$20 -> 부유세균 | F17: =시료인계서!C20 -> 평촌경영고등학교 | G17: =시료인계서!G20 -> BBA-1-
A18: =시료인계서!$C$4 -> 2026.06.10 | B18: ='입력1(학교시설명 등 기본사항 입력) 보고서1,2'!$I$15 -> 박정식 | C18: =시료인계서!$C$5 -> 평촌경영고등학교 | D18: 4층 2-4 | E18: =시료인계서!$B$21 -> 부유세균 | F18: =시료인계서!C21 -> 평촌경영고등학교 | G18: =시료인계서!G21 -> BBA-2-
A19: =시료인계서!$C$4 -> 2026.06.10 | B19: ='입력1(학교시설명 등 기본사항 입력) 보고서1,2'!$I$15 -> 박정식 | C19: =시료인계서!$C$5 -> 평촌경영고등학교 | D19: 1층 (도제)회계실무실습실 | E19: =시료인계서!$B$22 -> 부유세균 | F19: =시료인계서!C22 -> 평촌경영고등학교 | G19: =시료인계서!G22 -> BBA-3-
A20: =시료인계서!$C$4 -> 2026.06.10 | B20: ='입력1(학교시설명 등 기본사항 입력) 보고서1,2'!$I$15 -> 박정식 | C20: =시료인계서!$C$5 -> 평촌경영고등학교 | D20: 보건실 | E20: =시료인계서!$B$23 -> 낙하세균 | F20: =시료인계서!C23 -> 평촌경영고등학교 | G20: =시료인계서!G23 -> NBA-1-
A21: =시료인계서!$C$4 -> 2026.06.10 | B21: ='입력1(학교시설명 등 기본사항 입력) 보고서1,2'!$I$15 -> 박정식 | C21: =시료인계서!$C$5 -> 평촌경영고등학교 | D21: 보건실 | E21: =시료인계서!$B$24 -> 낙하세균 | F21: =시료인계서!C24 -> 평촌경영고등학교 | G21: =시료인계서!G24 -> NBA-2-
A22: =시료인계서!$C$4 -> 2026.06.10 | B22: ='입력1(학교시설명 등 기본사항 입력) 보고서1,2'!$I$15 -> 박정식 | C22: =시료인계서!$C$5 -> 평촌경영고등학교 | D22: 보건실 | E22: =시료인계서!$B$25 -> 낙하세균 | F22: =시료인계서!C25 -> 평촌경영고등학교 | G22: =시료인계서!G25 -> NBA-3-
A23: =시료인계서!$C$4 -> 2026.06.10 | B23: ='입력1(학교시설명 등 기본사항 입력) 보고서1,2'!$I$15 -> 박정식 | C23: =시료인계서!$C$5 -> 평촌경영고등학교 | D23: 급식시설 | E23: =시료인계서!$B$26 -> 낙하세균 | F23: =시료인계서!C26 -> 평촌경영고등학교 | G23: =시료인계서!G26 -> NBA-4-
A24: =시료인계서!$C$4 -> 2026.06.10 | B24: ='입력1(학교시설명 등 기본사항 입력) 보고서1,2'!$I$15 -> 박정식 | C24: =시료인계서!$C$5 -> 평촌경영고등학교 | D24: 급식시설 | E24: =시료인계서!$B$27 -> 낙하세균 | F24: =시료인계서!C27 -> 평촌경영고등학교 | G24: =시료인계서!G27 -> NBA-5-
A25: =시료인계서!$C$4 -> 2026.06.10 | B25: ='입력1(학교시설명 등 기본사항 입력) 보고서1,2'!$I$15 -> 박정식 | C25: =시료인계서!$C$5 -> 평촌경영고등학교 | D25: 급식시설 | E25: =시료인계서!$B$28 -> 낙하세균 | F25: =시료인계서!C28 -> 평촌경영고등학교 | G25: =시료인계서!G28 -> NBA-6-
A26: =시료인계서!$C$4 -> 2026.06.10 | B26: ='입력1(학교시설명 등 기본사항 입력) 보고서1,2'!$I$15 -> 박정식 | C26: =시료인계서!$C$5 -> 평촌경영고등학교 | E26: =시료인계서!$B$29 -> 0 | F26: =시료인계서!C29 -> 평촌경영고등학교 | G26: =시료인계서!G29 -> --
A27: =시료인계서!$C$4 -> 2026.06.10 | B27: ='입력1(학교시설명 등 기본사항 입력) 보고서1,2'!$I$15 -> 박정식 | C27: =시료인계서!$C$5 -> 평촌경영고등학교 | E27: =시료인계서!$B$32 -> 0 | F27: =시료인계서!C30 -> 평촌경영고등학교 | G27: =시료인계서!G30 -> --
A28: =시료인계서!$C$4 -> 2026.06.10 | B28: ='입력1(학교시설명 등 기본사항 입력) 보고서1,2'!$I$15 -> 박정식 | C28: =시료인계서!$C$5 -> 평촌경영고등학교 | E28: =시료인계서!$B$33 -> 0 | F28: =시료인계서!C31 -> 평촌경영고등학교 | G28: =시료인계서!G31 -> --
A29: =시료인계서!$C$4 -> 2026.06.10 | B29: ='입력1(학교시설명 등 기본사항 입력) 보고서1,2'!$I$15 -> 박정식 | C29: =시료인계서!$C$5 -> 평촌경영고등학교 | E29: =시료인계서!$B$34 -> 46183 | F29: =시료인계서!C32 -> 평촌경영고등학교 | G29: =시료인계서!G32 -> --
A30: =시료인계서!$C$4 -> 2026.06.10 | B30: ='입력1(학교시설명 등 기본사항 입력) 보고서1,2'!$I$15 -> 박정식 | C30: =시료인계서!$C$5 -> 평촌경영고등학교 | E30: =시료인계서!$B$35 -> 박정식 | F30: =시료인계서!C33 -> 평촌경영고등학교 | G30: =시료인계서!G33 -> --
G31: =시료인계서!G34 -> 0
G32: =시료인계서!G35 -> 0

Sheet 포집유량 보정
A1: 펌프유량 보정
A2: NO | B2: 측정자 | C2: 측정일 | D2: 학교명 | E2: 측정위치 | F2: 측정항목 | G2: 시료종류 | H2: 측정장비 | I2: 포집 유송(L/min) | K2: 평균 유속 (L/min) | L2: 포집시간 (min) | M2: 총포집유량(V) | N2: 온도 압력 보정 (V25℃,1기압)
I3: 측정 전 | J3: 측정 후
A4: 1 | F4: 포름알데하이드 | K4: =AVERAGE(I4:J4) -> #DIV/0! | M4: =K4*L4 -> #DIV/0!
A5: 2 | F5: 포름알데하이드 | K5: =AVERAGE(I5:J5) -> #DIV/0! | M5: =K5*L5 -> #DIV/0!
A6: 3 | F6: 총휘발성유기화합물 | K6: =AVERAGE(I6:J6) -> #DIV/0! | M6: =K6*L6 -> #DIV/0!
A7: 4 | F7: 총휘발성유기화합물 | K7: =AVERAGE(I7:J7) -> #DIV/0! | M7: =K7*L7 -> #DIV/0!
A8: 5 | F8: 부유세균 | I8: 100 | J8: 100 | K8: =AVERAGE(I8:J8) -> 100 | L8: 1 | M8: =K8*L8/1000 -> 0.1 | N8: =M8*(298/(273+'입력2(측정)'!T5)*('입력2(측정)'!M5/1013)) -> 0.098945534
A9: 6 | F9: 부유세균 | I9: 100 | J9: 100 | K9: =AVERAGE(I9:J9) -> 100 | L9: 1 | M9: =K9*L9/1000 -> 0.1 | N9: =M9*(298/(273+'입력2(측정)'!T6)*('입력2(측정)'!M6/1013)) -> 0.099107907
A10: 7 | F10: 부유세균 | I10: 100 | J10: 100 | K10: =AVERAGE(I10:J10) -> 100 | L10: 1 | M10: =K10*L10/1000 -> 0.1 | N10: =M10*(298/(273+'입력2(측정)'!T7)*('입력2(측정)'!M7/1013)) -> 0.098996267
A11: 8 | F11: 부유세균 | I11: 100 | J11: 100 | K11: =AVERAGE(I11:J11) -> 100 | L11: 1 | M11: =K11*L11/1000 -> 0.1 | N11: =M11*(298/(273+'입력2(측정)'!T8)*('입력2(측정)'!M8/1013)) -> #DIV/0!
A12: 9 | I12: 100 | J12: 100 | K12: =AVERAGE(I12:J12) -> 100 | L12: 1 | M12: =K12*L12/1000 -> 0.1 | N12: =M12*(298/(273+'입력2(측정)'!T9)*('입력2(측정)'!M9/1013)) -> 0.098729533
A13: 10 | I13: 100 | J13: 100 | K13: =AVERAGE(I13:J13) -> 100 | L13: 1 | M13: =K13*L13/1000 -> 0.1 | N13: =M13*(298/(273+'입력2(측정)'!T10)*('입력2(측정)'!M10/1013)) -> 0.099116711
G14: 석면 유량 온도, 압력 보정
I15: ='입력2(측정)'!N57 -> 0 | J15: ='입력2(측정)'!P57 -> 0 | K15: =AVERAGE(I15:J15) -> 0 | L15: 120 | M15: =L15*K15 -> 0 | N15: =M15*(298/(273+'입력2(측정)'!H57)*('입력2(측정)'!L57/1013)) -> 0
I16: ='입력2(측정)'!N58 -> 0 | J16: ='입력2(측정)'!P58 -> 0 | K16: =AVERAGE(I16:J16) -> 0 | L16: 120 | M16: =L16*K16 -> 0 | N16: =M16*(298/(273+'입력2(측정)'!H58)*('입력2(측정)'!L58/1013)) -> 0
I17: ='입력2(측정)'!N59 -> 0 | J17: ='입력2(측정)'!P59 -> 0 | K17: =AVERAGE(I17:J17) -> 0 | L17: 120 | M17: =L17*K17 -> 0 | N17: =M17*(298/(273+'입력2(측정)'!H59)*('입력2(측정)'!L59/1013)) -> 0
I18: ='입력2(측정)'!N60 -> 0 | J18: ='입력2(측정)'!P60 -> 0 | K18: =AVERAGE(I18:J18) -> 0 | L18: 120 | M18: =L18*K18 -> 0 | N18: =M18*(298/(273+'입력2(측정)'!H60)*('입력2(측정)'!L60/1013)) -> 0
I19: ='입력2(측정)'!N61 -> 0 | J19: ='입력2(측정)'!P61 -> 0 | K19: =AVERAGE(I19:J19) -> 0 | L19: 120 | M19: =L19*K19 -> 0 | N19: =M19*(298/(273+'입력2(측정)'!H61)*('입력2(측정)'!L61/1013)) -> 0
I20: ='입력2(측정)'!N62 -> 0 | J20: ='입력2(측정)'!P62 -> 0 | K20: =AVERAGE(I20:J20) -> 0 | L20: 120 | M20: =L20*K20 -> 0 | N20: =M20*(298/(273+'입력2(측정)'!H62)*('입력2(측정)'!L62/1013)) -> 0

Sheet 부유세균(시험기록부)
A1: 시 험 기 록 부 | W1: 시험담당자 | Y1: 기술책임자
A2: 1. 일반사항 oo
A3: 업 체 명 | C3: ='입력1(학교시설명 등 기본사항 입력) 보고서1,2'!C2 -> 평촌경영고등학교 | I3: 시 설 명 | M3: ='입력1(학교시설명 등 기본사항 입력) 보고서1,2'!C2 -> 평촌경영고등학교
A4: 측 정 일 자 | C4: ='입력1(학교시설명 등 기본사항 입력) 보고서1,2'!C13 -> 2026.06.10 | I4: 분석일자 | M4: 2026년 06월 12일 ~ 06월 13일
A5: 측 정 자 | C5: ='입력1(학교시설명 등 기본사항 입력) 보고서1,2'!I15 -> 박정식 | I5: 분 석 자 | M5: ='입력2(측정)'!B1 -> 유재혁
A6: 시료채취지점 | C6: ='입력2(측정)'!$B46 -> 5층 2-11반 | G6: ='입력2(측정)'!B47 -> 4층 2-4반 | K6: ='입력2(측정)'!B48 -> 1층 (도제)회계실무실습실 | O6: ='입력2(측정)'!B49 -> 0 | S6: - | W6: -
A8: 온 도(℃) | C8: =보고서3!G95 -> 25.5 | G8: =보고서3!G96 -> 25.1 | K8: =보고서3!G97 -> 25.733333 | O8: =보고서3!G98 -> - | S8: - | W8: -
A9: 습 도(%) | C9: =보고서3!G102 -> 41.39 | G9: =보고서3!G103 -> 45.666667 | K9: =보고서3!G104 -> 51.7 | O9: =보고서3!G105 -> - | S9: - | W9: -
A10: 기압(mmHg) | C10: ='입력2(측정)'!M5 -> 1004 | G10: ='입력2(측정)'!M6 -> 1004.3 | K10: ='입력2(측정)'!M7 -> 1005.3 | O10: ='입력2(측정)'!M8 -> 0 | S10: - | W10: -
A12: 2. 시험방법 실내공기질 공정시험기준 ES 02701.1e 실내 공기 중 총부유세균 측정방법 - 충돌법
A14: 2. 분석내용
A15: ※ 채취공기량 계산식
K16: V(25°C, 1atm) : 25 °C, 1기압일 때 기체의 부피(m3) T(25°C): 25 °C의 절대온도(°K),(298 °K = 273+25 °C) P(1atm) : 1기압(atm) V : 실제로 채취한 기체의 부피(m3) = (Qave * 시간)/103 T2 : 기체를 채취할 때의 절대온도(°K), (°K=273+°C) P2 : 기체를 채취할 때의 기압(atm)
A18: 시료채취지점 | C18: =C6 -> 5층 2-11반 | G18: =G6 -> 4층 2-4반 | K18: =K6 -> 1층 (도제)회계실무실습실 | O18: =O6 -> 0 | S18: =S6 -> - | W18: =W6 -> -
A19: ④ 부 유 세 균 (CFU/m3) | B19: ※농도계산식 | K19: C : 실내 공기 중 총부유세균의 농도(CFU/m3) CFU : 보정된 집락수 V(25°C, 1atm) : 환산된 채취공기량(m3)
B20: 시료번호 | C20: BBA-01 | G20: BBA-02 | K20: BBA-03 | O20: - | S20: - | W20: -
B21: C | C21: =C22/C23 -> 80.852563 | G21: =G22/G23 -> 242.16029 | K21: =K22/K23 -> 30.304173 | O21: - | S21: - | W21: -
B22: CFU | C22: ='입력2(측정)'!Y46 -> 8 | G22: ='입력2(측정)'!Y47 -> 24 | K22: ='입력2(측정)'!Y48 -> 3 | O22: - | S22: - | W22: -
B23: V(25 °C,1atm) | C23: ='포집유량 보정'!N8 -> 0.098945534 | G23: ='포집유량 보정'!N9 -> 0.099107907 | K23: ='포집유량 보정'!N10 -> 0.098996267 | O23: - | S23: - | W23: -
B24: V | C24: ='포집유량 보정'!N8 -> 0.098945534 | G24: ='포집유량 보정'!N9 -> 0.099107907 | K24: ='포집유량 보정'!N10 -> 0.098996267 | O24: - | S24: - | W24: -
A26: 3. 계산식
A27: 시료채취지점 | C27: 계산식
A28: =C18 -> 5층 2-11반 | L28: =C22 -> 8
L29: =C24 -> 0.098945534 | M29: X | N29: (273+25) | P29: X | Q29: =C10 -> 1004
M30: (273+ | O30: =C8 -> 25.5 | P30: ) | Q30: X | R30: 1013
A31: =G18 -> 4층 2-4반 | L31: =G22 -> 24
L32: =G24 -> 0.099107907 | M32: X | N32: (273+25) | P32: X | Q32: =G10 -> 1004.3
M33: (273+ | O33: =G8 -> 25.1 | P33: ) | Q33: X | R33: 1013
A34: =K18 -> 1층 (도제)회계실무실습실 | L34: =K22 -> 3
L35: =K24 -> 0.098996267 | M35: X | N35: (273+25) | P35: X | Q35: =K10 -> 1005.3
M36: (273+ | O36: =K8 -> 25.733333 | P36: ) | Q36: X | R36: 1013
A37: =O18 -> 0 | L37: =O22 -> -
L38: =O24 -> - | M38: X | N38: (273+25) | P38: X | Q38: =O10 -> 0
M39: (273+ | O39: =O8 -> - | P39: ) | Q39: X | R39: 1013
A40: =S18 -> - | L40: =S21 -> -
L41: ='포집유량 보정'!U12 -> 0 | M41: X | N41: (273+25) | P41: X | Q41: ='입력2(측정)'!V14 -> 0
M42: (273+ | O42: ='입력2(측정)'!AB14 -> 0 | P42: ) | Q42: X | R42: 1013
A43: =W6 -> - | L43: =W21 -> -
L44: ='포집유량 보정'!U16 -> 0 | M44: X | N44: (273+25) | P44: X | Q44: ='입력2(측정)'!V17 -> 0
M45: (273+ | O45: ='입력2(측정)'!AB17 -> 0 | P45: ) | Q45: X | R45: 1013

Sheet 부유세균 환산표
A2: r | B2: Pr
A3: 1 | B3: 1
A4: 2 | B4: 2
A5: 3 | B5: 3
A6: 4 | B6: 4
A7: 5 | B7: 5
A8: 6 | B8: 6
A9: 7 | B9: 7
A10: 8 | B10: 8
A11: 9 | B11: 9
A12: 10 | B12: 10
A13: 11 | B13: 11
A14: 12 | B14: 12
... A401: 399 | B401: 2427
A402: 400 | B402: -

Sheet 낙하세균(시험기록부)
A1: 시 험 기 록 부 | O1: 시험담당자 | Q1: 기술책임자
A2: 1. 일반사항 oo
A3: 업 체 명 | C3: ='입력1(학교시설명 등 기본사항 입력) 보고서1,2'!C2 -> 평촌경영고등학교 | I3: 시 설 명 | M3: ='입력1(학교시설명 등 기본사항 입력) 보고서1,2'!C2 -> 평촌경영고등학교
A4: 측 정 일 자 | C4: ='입력1(학교시설명 등 기본사항 입력) 보고서1,2'!C13 -> 2026.06.10 | I4: 분석일자 | M4: ='부유세균(시험기록부)'!M4 -> 2026년 06월 12일 ~ 06월 13일
A5: 측 정 자 | C5: ='입력1(학교시설명 등 기본사항 입력) 보고서1,2'!I15 -> 박정식 | I5: 분 석 자 | M5: ='입력2(측정)'!B1 -> 유재혁
A6: 시료채취지점 | C6: ='입력2(측정)'!B52 -> 급식시설 | G6: ='입력2(측정)'!B53 -> 보건실
A8: 온 도(℃) | C8: - | G8: -
A9: 습 도(%) | C9: - | G9: -
A10: 기압(mmHg) | C10: - | G10: -
A12: 2. 시험방법 학교 환경위생 및 식품위생 점검기준, 2장 점검방법 및 기준, 마항 학교시설에서의 공기질등, 5)항 낙하세균
A14: 2. 분석내용
A15: ※ 채취공기량 계산식
A16: 없음 | K16: -
A18: 시료채취지점 | C18: ='입력2(측정)'!B52 -> 급식시설 | G18: ='입력2(측정)'!B53 -> 보건실
A19: ④ 낙하세균 (CFU) | B19: 시료번호 | C19: NBA-1~3 | G19: NBA-4~6
B20: CFU | C20: =C26 -> 0 | G20: =C29 -> 2
A22: 3. 결과
A23: 시료채취지점 | C23: 시료번호
A24: ='입력2(측정)'!B52 -> 급식시설 | C24: NBA-01 | I24: NBA-02 | O24: NBA-03
C25: ='입력2(측정)'!Y52 -> 0 | I25: ='입력2(측정)'!AE52 -> 0 | O25: ='입력2(측정)'!AL52 -> 0
C26: =SUM(C25+I25+O25) -> 0
A27: ='입력2(측정)'!B53 -> 보건실 | C27: NBA-04 | I27: NBA-05 | O27: NBA-06
C28: ='입력2(측정)'!Y53 -> 0 | I28: ='입력2(측정)'!AE53 -> 1 | O28: ='입력2(측정)'!AL53 -> 1
C29: =C28+I28+O28 -> 2

Sheet 석면 시험기록부
A1: 시 험 기 록 부 | W1: 시험담당자 | Y1: 기술책임자
A2: 1. 일반사항 oo
A3: 업 체 명 | C3: ='입력1(학교시설명 등 기본사항 입력) 보고서1,2'!C2 -> 평촌경영고등학교 | I3: 시 설 명 | M3: ='입력1(학교시설명 등 기본사항 입력) 보고서1,2'!C2 -> 평촌경영고등학교
A4: 측 정 일 자 | C4: ='입력1(학교시설명 등 기본사항 입력) 보고서1,2'!C13 -> 2026.06.10 | I4: 분석일자 | M4: 2026년 03월 28일 ~ 03월 29일
A5: 측 정 자 | C5: ='입력1(학교시설명 등 기본사항 입력) 보고서1,2'!I15 -> 박정식 | I5: 분 석 자 | M5: ='입력2(측정)'!B1 -> 유재혁
A6: 시료채취지점 | C6: ='입력2(측정)'!B57 -> 0 | G6: ='입력2(측정)'!B58 -> 0 | K6: ='입력2(측정)'!B59 -> 0 | O6: ='입력2(측정)'!B60 -> 0 | S6: ='입력2(측정)'!B61 -> 0 | W6: ='입력2(측정)'!B62 -> 0
A8: 온 도(℃) | C8: ='입력2(측정)'!H57 -> 0 | G8: ='입력2(측정)'!T6 -> 25.1 | K8: ='입력2(측정)'!T7 -> 25.733333 | O8: ='입력2(측정)'!T8 -> #DIV/0! | S8: ='입력2(측정)'!T9 -> 26.6 | W8: ='입력2(측정)'!T10 -> 25.4
A9: 습 도(%) | C9: ='입력2(측정)'!J57 -> 0 | G9: ='입력2(측정)'!J58 -> 0 | K9: ='입력2(측정)'!J59 -> 0 | O9: ='입력2(측정)'!J60 -> 0 | S9: ='입력2(측정)'!J61 -> 0 | W9: ='입력2(측정)'!J62 -> 0
A10: 기압(mmHg) | C10: ='입력2(측정)'!L57 -> 0 | G10: ='입력2(측정)'!L58 -> 0 | K10: ='입력2(측정)'!L59 -> 0 | O10: ='입력2(측정)'!L60 -> 0 | S10: ='입력2(측정)'!L61 -> 0 | W10: ='입력2(측정)'!L62 -> 0
A12: 2. 시험방법 실내공기질 공정시험기준 ES 02701.1e 실내 공기 중 총부유세균 측정방법 - 충돌법
A14: 2. 분석내용
A15: ※ 채취공기량 계산식
K16: V(25°C, 1atm) : 25 °C, 1기압일 때 기체의 부피(m3) T(25°C): 25 °C의 절대온도(°K),(298 °K = 273+25 °C) P(1atm) : 1기압(atm) V : 실제로 채취한 기체의 부피(m3) = (Qave * 시간)/103 T2 : 기체를 채취할 때의 절대온도(°K), (°K=273+°C) P2 : 기체를 채취할 때의 기압(atm)
A17: ※ 농도 계산식
K18: C : 공기 중 석면 및 섬유상 먼지의 농도(개/cm3) A : 유효 포집면적(mm2) N₁: 위상차현미경으로 계측한 시료의 총 섬유수(개) N₂: 위상차현미경으로 계측한 바탕시료의 총 섬유수(개) a : 현미경으로 계측한 1시야의 면적(mm2) V(25°C, 1atm) : 환산한 채취 공기량(L) n : 계수한 시야의 총수(개)
A19: 시료채취지점 | C19: =C6 -> 0 | G19: =G6 -> 0 | K19: =K6 -> 0 | O19: =O6 -> 0 | S19: =S6 -> 0 | W19: =W6 -> 0
A20: ④ 부 유 세 균 (CFU/m3) | B20: 시료번호 | C20: 직접입력 | G20: 직접입력 | K20: 직접입력 | O20: 직접입력 | S20: 직접입력 | W20: 직접입력
B21: C | C21: =C22*(C23-C24)/(C25*C26*C27)*1/1000 -> #DIV/0! | G21: =G22*(G23-G24)/(G25*G26*G27)*1/1000 -> #DIV/0! | K21: =K22*(K23-K24)/(K25*K26*K27)*1/1000 -> #DIV/0! | O21: =O22*(O23-O24)/(O25*O26*O27)*1/1000 -> #DIV/0! | S21: =S22*(S23-S24)/(S25*S26*S27)*1/1000 -> #DIV/0! | W21: =W22*(W23-W24)/(W25*W26*W27)*1/1000 -> #DIV/0!
B22: A | C22: 385 | G22: 385 | K22: 385 | O22: 385 | S22: 385 | W22: 385
B23: N1 | C23: 24 | G23: 18.5 | K23: 12 | O23: 13 | S23: 17 | W23: 19
B24: N2 | C24: 0 | G24: =G25/G26 -> #DIV/0! | K24: =K25/K26 -> #DIV/0! | O24: =O25/O26 -> #DIV/0! | S24: =S25/S26 -> #DIV/0! | W24: =W25/W26 -> #DIV/0!
B25: α | C25: 0.00785 | G25: 0.00785 | K25: 0.00785 | O25: 0.00785 | S25: 0.00785 | W25: 0.00785
B26: V(25 °C,1atm) | C26: ='포집유량 보정'!N15 -> 0 | G26: ='포집유량 보정'!N16 -> 0 | K26: ='포집유량 보정'!N17 -> 0 | O26: ='포집유량 보정'!N18 -> 0 | S26: ='포집유량 보정'!N19 -> 0 | W26: ='포집유량 보정'!N20 -> 0
B27: n | C27: 100 | G27: 100 | K27: 100 | O27: 100 | S27: 100 | W27: 100
A29: 3. 계산식
A30: 시료채취지점 | C30: 계산식
A31: =C19 -> 0 | L31: 385 | M31: X | N31: ( | O31: =C23 -> 24 | P31: - | Q31: =C24 -> 0 | R31: )
L32: =C22 -> 385 | M32: X | N32: =C26 -> 0 | P32: X | Q32: =C27 -> 100 | R32: X | S32: 1000
A33: =G19 -> 0 | L33: 385 | M33: X | N33: ( | O33: =G23 -> 18.5 | P33: - | Q33: =-G24 -> #DIV/0! | R33: )
L34: =C25 -> 0.00785 | M34: X | N34: =G26 -> 0 | P34: X | Q34: 100 | R34: X | S34: 1000
A35: =K19 -> 0 | L35: 385 | M35: X | N35: ( | O35: =K23 -> 12 | P35: - | Q35: =-K24 -> #DIV/0! | R35: )
L36: =C28 -> 0 | M36: X | N36: =K26 -> 0 | P36: X | Q36: 100 | R36: X | S36: 1000
A37: =O19 -> 0 | L37: 385 | M37: X | N37: ( | O37: =O23 -> 13 | P37: - | Q37: =O24 -> #DIV/0! | R37: )
L38: =C31 -> 0 | M38: X | N38: =O26 -> 0 | P38: X | Q38: 100 | R38: X | S38: 1000
A39: =S19 -> 0 | L39: 385 | M39: X | N39: ( | O39: =S23 -> 17 | P39: - | Q39: =S24 -> #DIV/0! | R39: )
L40: =C33 -> 0 | M40: X | N40: =S26 -> 0 | P40: X | Q40: 100 | R40: X | S40: 1000
A41: =W6 -> 0 | L41: 385 | M41: X | N41: ( | O41: =-W23 -> -19 | P41: - | Q41: =-W24 -> #DIV/0! | R41: )
L42: =C35 -> 0 | M42: X | N42: =W26 -> 0 | P42: X | Q42: 100 | R42: X | S42: 1000

Sheet 드롭다운 메뉴_지우지말것!
A1: 정수기 | B1: 기숙사 | C1: 환기장치 | D1: 측정항목1 | E1: 측정항목2 | F1: 시료번호 | G1: 측정자 | H1: 유량보정 항목
A2: 상수도 | B2: ○ | C2: 기계 | D2: 포름알데하이드 | E2: 낙하세균,부유세균,포름알데하이드,총유기화학물,석면 | F2: HCHO | G2: 이진혁 | H2: 포름알데하이드
A3: 지하수 | B3: × | C3: 자연 | D3: 총유기화합물 | E3: 낙하세균,부유세균,포름알데하이드,총유기화학물 | F3: VOC | G3: 박정식 | H3: 총휘발성유기화합물
A4: 기타 | C4: 자연, 기계 | D4: 미세먼지 | E4: 낙하세균,부유세균 | F4: PM2.5 | G4: 김은주 | H4: 부유세균
D5: 초미세먼지 | E5: 낙하세균 | F5: PM10 | G5: 김종수 | H5: 곰팡이
D6: 부유곰팡이 | E6: 부유세균 | F6: BMD | G6: 박정식, 김은주 | H6: 미세먼지
D7: 부유세균 | F7: BBA | H7: 총미세먼지
D8: 낙하세균 | F8: NBA
D9: 진득이 | F9: JIN

Sheet 시료 접수대장
A2: NO | B2: 측정 및 분석 항목 | C2: 측정위치 | D2: 시료번호1 | E2: 시료번호2 | F2: 비고
A3: 1
A4: 2
A5: 3
A6: 4
A7: 5
A8: 6
A9: 7
A10: 8
A11: 9
A12: 10
A13: 11
A14: 12
... A52: 50
